Workbook

Sheet Mode d'emploi
A1: HEAT — Catalogue des leviers, version 3
A2: Régénéré depuis le code du jeu le 26/08/2026 — jeu en version v0.9.1.
A4: Ce que contient ce fichier
A5: Onglet Catalogue — les leviers réellement jouables, extraits automatiquement du fichier du jeu. Coûts, seuils, latences,
A6: époques, prérequis, probabilités, contre-leviers et combinaisons sont les valeurs du moteur, pas des estimations.
A7: Onglet Non retenus — les leviers du catalogue d'août jamais construits, chacun avec le verdict qui l'écarte.
A8: Onglet Correspondance — les identifiants qui ne désignent pas le même levier dans le catalogue d'août et dans le jeu.
A9: Onglet Contrôles — répartitions et cohérence des contre-leviers, recalculées par formule à l'ouverture du fichier.
A11: Comment il a été produit
A12: Les colonnes descriptives sont lues dans le code du jeu : elles ne peuvent pas diverger de ce qui se joue.
A13: Le fichier est régénérable à chaque version. C'est une photographie du jeu, pas un document à éditer à la main :
A14: une correction saisie ici serait perdue à la prochaine génération, et elle ne changerait rien au jeu.
... A24: Seules les colonnes Ancrage réel daté et Limite documentée renvoient à des faits, et chacune porte sa date.

Sheet Catalogue
A1: ID | B1: Camp | C1: Famille | D1: Levier | E1: Alias polémique | F1: Portée | G1: Coût politique | H1: Coût capital | I1: Coût attention | J1: Latence (tours) | K1: Seuil de perçu | L1: Époque | M1: Prérequis | N1: Réussite (%) | O1: Réversibilité | P1: Robustesse | Q1: Contre-levier | R1: Piège | S1: Combinaisons | T1: Puissance réelle (1-5) | U1: Effet dans le jeu | V1: Mécanisme | W1: Ancrage réel daté | X1: Limite documentée | Y1: Rôle dans le jeu (arbitrage août)
A2: A01 | B2: Actif | C2: Réglementaire | D2: Tarification carbone nationale | E2: matraquage fiscal | F2: Bloc | G2: 4 | K2: 45 | L2: 1 | N2: 78 | O2: Facile à annuler | P2: Élevée | Q2: T60 | S2: Le chèque avec la taxe (avec A31) | T2: 4 | U2: Contrainte +20, friction +22. Friction divisée par deux si la redistribution a été installée. | V2: Un prix sur la tonne renchérit l'usage fossile dans toute l'économie du bloc, sans désigner de secteur. L'effet est large mais la douleur est visible et datée. | W2: Taxe carbone française 2014-2018, gelée en décembre 2018 après les Gilets jaunes. Prix du carbone suédois autour de 120 €/t depuis 2018, maintenu. | X2: Sans redistribution visible, la friction s'accumule jusqu'au retour de flamme : taxe française gelée en 2018, tarification australienne abrogée en 2014. | Y2: Noyau · Émissions — la tarification icônique, et le générateur de friction du jeu (paire avec A31)
A3: A02 | B3: Actif | C3: Réglementaire | D3: Marché de quotas (ETS) | E3: usine à gaz bruxelloise | F3: Bloc | G3: 3 | K3: 45 | L3: 1 | N3: 100 | O3: Difficile à annuler | P3: Élevée | Q3: T22 | S3: Plafond étanche (avec A03) | T3: 4 | U3: Contrainte +18, friction +9. | V3: Plafond décroissant sur les émetteurs, échangeable. Le coût passe par les prix sans jamais apparaître comme un impôt : friction citoyenne faible. | W3: EU ETS depuis 2005 ; prix passé de 5 € (2017) à plus de 80 €/t (2023). ETS2 bâtiment et transport prévu pour 2027. | X3: Vulnérable aux exemptions sectorielles obtenues discrètement : le plafond tient, le périmètre se vide. | Y3: Noyau · Émissions — l'outil de fond, plafond décroissant, faible friction citoyenne
A4: A03 | B4: Actif | C4: Réglementaire | D4: Ajustement carbone aux frontières | E4: protectionnisme vert | F4: Bloc | G4: 4 | K4: 35 | L4: 2 | M4: un prix du carbone intérieur — sans lui, il n'y a rien à ajuster à la frontière | N4: 100 | O4: Difficile à annuler | P4: Moyenne | Q4: T53 | S4: Plafond étanche (avec A02) | T4: 3 | U4: Contrainte +12 ici, +5 sur les autres blocs riches. Immunise le bloc contre le whataboutisme. | V4: Taxe l'empreinte des importations au niveau du prix intérieur. Supprime l'argument « nos usines partiront ailleurs » en supprimant l'avantage du moins-disant. | W4: MACF/CBAM européen : phase déclarative depuis octobre 2023, financière à partir de 2026. | X4: Provoque des représailles commerciales et des accusations de protectionnisme vert de la part des blocs exportateurs. | Y4: Noyau · Émissions — contre structurel du whataboutisme (T02) et de la fuite de carbone (T53)
A5: A04 | B5: Actif | C5: Réglementaire | D5: Norme d'émission véhicules | E5: norme punitive | F5: Bloc | G5: 2 | J5: 1 | L5: 1 | N5: 100 | O5: Difficile à annuler | P5: Élevée | Q5: T52 | T5: 4 | U5: Contrainte +19 au tour suivant, friction +7. | V5: Contraint les constructeurs, pas les conducteurs. Le coût est industriel, invisible du citoyen, et l'effet court sur tout le parc renouvelé. | W5: Règlement européen 95 gCO₂/km ; fin du thermique neuf actée pour 2035, avec clause de revoyure 2026. | X5: Cible privilégiée des exemptions technologiques : une niche inscrite dans le texte suffit à en vider l'effet. | Y5: Noyau · Émissions — contrainte industrielle sans coût budgétaire ; contre direct de T52
A6: A05 | B6: Actif | C6: Réglementaire | D6: Interdiction de vente datée | E6: interdiction idéologique | F6: Bloc | G6: 4 | J6: 1 | K6: 55 | L6: 2 | N6: 72 | O6: Facile à annuler | P6: Moyenne | Q6: T71 | T6: 5 | U6: Contrainte +27 au tour suivant, friction +17. | V6: Une date butoir déclenche l'anticipation industrielle bien avant l'échéance : les investissements se réorientent dès l'annonce. | W6: Fin du thermique neuf 2035 (UE) ; interdiction des chaudières fioul en France en 2022 ; interdiction des ampoules à incandescence. | X6: Plus la date est lointaine, plus elle est facile à voter et à annuler. Une clause de revoyure suffit à la rouvrir. | Y6: Noyau · Émissions — déclenche l'anticipation industrielle dès l'annonce (puissance 5)
A7: A07 | B7: Actif | C7: Réglementaire | D7: Fin des subventions aux fossiles | E7: hausse des prix à la pompe | F7: Mondial | G7: 5 | L7: 1 | N7: 50 | O7: Facile à annuler | P7: Élevée | Q7: T39 | T7: 5 | U7: Contrainte +9 et friction +11 sur tous les blocs. | V7: Supprime la subvention à la consommation fossile. Aucune technologie à déployer, aucun délai de mise en œuvre : seulement une décision budgétaire. | W7: Engagement du G20 depuis 2009 ; subventions explicites toujours de l'ordre de 1 200 Md$/an selon le FMI. | X7: Politiquement très difficile : dans plusieurs blocs, le prix subventionné du carburant tient lieu de contrat social, et sa suppression a déclenché des émeutes. | Y7: Noyau · Émissions — meilleur rapport effet/coût du catalogue, portée mondiale
A8: A09 | B8: Actif | C8: Narratif | D8: Objectif net zéro 2050 | F8: Mondial | I8: 1 | L8: 1 | N8: 100 | O8: Facile à annuler | P8: Faible | Q8: A12 | R8: oui | T8: 1 | U8: Perçu +9 partout immédiatement. Aucune contrainte, jamais. | V8: Marque des points d'opinion sans engager la moindre décision : aucune étape intermédiaire, aucun décideur en exercice concerné. | W8: Généralisation des annonces net zéro 2050 sans trajectoire 2030 intermédiaire. | X8: Un objectif à trente-cinq ans sans étape intermédiaire n'engage aucun décideur en exercice. Les émissions, elles, se comptent chaque année. | Y8: Noyau · Piège — le plus répandu. Points d'opinion immédiats, zéro tonne évitée
A9: A10 | B9: Actif | C9: Réglementaire | D9: Normes d'efficacité des appareils | F9: Bloc | G9: 1 | L9: 1 | N9: 100 | O9: Difficile à annuler | P9: Élevée | Q9: T73 | T9: 3 | U9: Contrainte +11, friction +1. Aucun contre-levier connu. | V9: Retire du marché les produits les moins efficaces. Effet cumulatif sur des décennies, sans que personne ne s'en aperçoive. | W9: Étiquetage énergétique et écoconception UE ; sortie de l'incandescence. Consommation moyenne d'un réfrigérateur divisée par trois depuis 1990. | X9: Aucun effet spectaculaire, donc aucun gain d'opinion — et aussi peu de prise pour l'adversaire, qui n'a pas d'angle d'attaque sur un seuil technique. | Y9: Noyau · Émissions — le levier invisible : coût 1, aucun contre-levier. Enseigne que l'efficace n'est pas spectaculaire
A10: A11 | B10: Actif | C10: Réglementaire | D10: Réduction des fuites de méthane | E10: contrainte sur les éleveurs | F10: Bloc | G10: 2 | K10: 25 | L10: 1 | N10: 100 | O10: Difficile à annuler | P10: Élevée | Q10: T22 | S10: Le coup de Kigali (avec A67) | T10: 4 | U10: Contrainte +13, friction +2. Effet en quelques années, contre une à deux décennies pour la plupart des autres. | V10: Le méthane a un pouvoir de réchauffement 80 fois supérieur au CO₂ sur vingt ans, mais une durée de vie courte : colmater agit dans la décennie, pas dans le siècle. | W10: Global Methane Pledge (2021), plus de 150 signataires ; règlement méthane européen (2024) ; détection satellitaire opérationnelle depuis 2023. | X10: Ne remplace rien : c'est un gain de temps, pas une trajectoire. Le CO₂ reste le stock qui compte. | Y10: Noyau · Émissions — le SEUL levier actif à effet rapide. Indispensable à l'équilibrage
A11: A12 | B11: Actif | C11: Réglementaire | D11: Loi-cadre climat contraignante | E11: carcan juridique | F11: Bloc | G11: 5 | K11: 55 | L11: 2 | N11: 62 | O11: Irréversible | P11: Élevée | Q11: T21 | S11: Trajectoire opposable (avec A63) | T11: 5 | U11: Verrouille le bloc : les mesures y résistent au retour de flamme et aux exemptions. | V11: Inscrit une trajectoire et un budget carbone dans la loi. Les mesures suivantes deviennent l'exécution d'une obligation, plus des choix révocables. | W11: UK Climate Change Act (2008), adopté à cinq voix contre. Loi Énergie-Climat française (2019). | X11: Exige un perçu élevé au moment du vote. Après polarisation, la fenêtre se referme pour toute la partie. | Y11: Pilier · Verrou — budgets pluriannuels contraignants, chaque écart devient attaquable
A12: A15 | B12: Actif | C12: Réglementaire | D12: Reporting extra-financier obligatoire | E12: paperasse extra-financière | F12: Bloc | G12: 2 | L12: 2 | N12: 100 | O12: Facile à annuler | P12: Moyenne | Q12: T70 | T12: 3 | U12: Contrainte +7 et perçu +5 : l'exposition carbone devient visible des investisseurs. | V12: Ce qui est mesuré et publié devient un risque financier. Le capital se retire avant que la réglementation ne morde. | W12: CSRD européenne (2022), largement allégée par le paquet omnibus de 2025. | X12: Démontré détricotable : la simplification administrative vide la norme sans jamais l'abroger. | Y12: Noyau · Verrou — PROMU : contre-levier de quatre cartes du noyau (T05, T20, T51, P01). Charnière de la couche institutionnelle
A13: A17 | B13: Actif | C13: Réglementaire | D13: Interdiction de la publicité fossile | E13: censure publicitaire | F13: Bloc | G13: 2 | K13: 40 | L13: 2 | N13: 70 | O13: Facile à annuler | P13: Moyenne | Q13: T31 | S13: Coupure médiatique (avec A54) | T13: 2 | U13: L'adversaire perd 1 point d'Attention pendant deux tours. | V13: Coupe l'accès du camp adverse à sa ressource principale. Effet indirect, mais il s'applique à toutes ses campagnes suivantes. | W13: Amsterdam (2020) ; loi Climat et Résilience française (2021), périmètre finalement restreint au fossile pur. | X13: Le greenwashing contourne l'interdiction en déplaçant le message vers l'entreprise plutôt que le produit. | Y13: Signature — le seul levier actif qui attaque directement la ressource Attention adverse
A14: A18 | B14: Actif | C14: Économique | D14: Subvention massive au déploiement | E14: gouffre à subventions | F14: Mondial | H14: 5 | J14: 2 | L14: 1 | N14: 100 | O14: Difficile à annuler | P14: Élevée | Q14: T67 | S14: La courbe s'effondre (avec A40) | T14: 5 | U14: Indice technologique +18 dans deux tours. Profite à tous les blocs, y compris à l'adversaire. | V14: Payer le déploiement fait descendre la courbe d'apprentissage. Le prix baisse pour tout le monde, définitivement. | W14: EEG allemand 2000-2015, environ 200 Md€, à l'origine de la chute mondiale du prix du photovoltaïque (−90 % entre 2010 et 2020). | X14: Passager clandestin inversé : vous payez, les autres blocs en bénéficient gratuitement. Le gain d'opinion national est nul. | Y14: Noyau · Émissions — courbe d'apprentissage : payé par un bloc, bénéficie à tous. Prouve mécaniquement que l'action marche
A15: A19 | B15: Actif | C15: Économique | D15: Politique industrielle verte | E15: subventions clientélistes | F15: Bloc | H15: 5 | L15: 1 | N15: 100 | O15: Facile à annuler | P15: Élevée | Q15: T50 | T15: 4 | U15: Contrainte +16, friction −4. Achète l'adhésion au lieu de contraindre. | V15: Crédits d'impôt et commandes publiques rendent la décarbonation rentable. Les industriels deviennent la coalition au lieu de l'opposition. | W15: Inflation Reduction Act américain (2022), environ 369 Md$ climat ; Net-Zero Industry Act européen. | X15: Cible directe de la capture de subvention : l'aide est encaissée sans que la trajectoire change. | Y15: Noyau · Coalition — acheter l'adhésion plutôt que contraindre ; cible du piège T50
A16: A20 | B16: Actif | C16: Économique | D16: Contrat pour différence | E16: prix garantis à vie | F16: Bloc | H16: 3 | L16: 2 | M16: une politique industrielle ou une subvention au déploiement déjà engagée | N16: 100 | O16: Difficile à annuler | P16: Élevée | Q16: T66 | S16: Capital dérisqué (avec A21) | T16: 4 | U16: Contrainte +14, et plafond +6 s'il a été abaissé par l'adversaire. Le coût du capital chute. | V16: L'État garantit un prix de vente. Le risque disparaît, le taux d'actualisation s'effondre, le projet se finance. | W16: CfD britanniques sur l'éolien en mer : prix adjugés divisés par trois entre 2015 et 2022. | X16: Levier discret et sans récit : il ne rapporte aucun point d'opinion, ce qui le rend rarement prioritaire. | Y16: Noyau · Émissions — PROMU : contre du piège P07. C'est le CfD qui rend le CCS sur centrale économiquement absurde
A17: A21 | B17: Actif | C17: Technologique | D17: Réseau électrique et stockage | F17: Bloc | H17: 4 | L17: 1 | N17: 100 | O17: Difficile à annuler | P17: Élevée | Q17: T40 | S17: Capital dérisqué (avec A20) | T17: 4 | U17: Contrainte +6, et plafond +18 s'il a été abaissé. Prérequis physique de tous les leviers électriques. | V17: Sans réseau ni flexibilité, l'électrification sature : les renouvelables sont écrêtés et les usages ne basculent pas. | W17: Files d'attente de raccordement de plusieurs années en Europe et aux États-Unis ; le réseau est devenu le premier goulot. | X17: Aucun effet visible dans le tour. C'est un levier qui n'existe que par ce qu'il rend possible ensuite. | Y17: Noyau · Émissions — prérequis physique : sans réseau, les leviers électriques saturent
A18: A22 | B18: Actif | C18: Économique | D18: Compensation carbone volontaire | F18: Bloc | H18: 1 | L18: 1 | N18: 100 | O18: Facile à annuler | P18: Faible | Q18: A15 | R18: oui | T18: 1 | U18: Contrainte +2 seulement. Crédibilité −8 quand l'écart est révélé. | V18: Semble neutraliser vos émissions résiduelles pour presque rien. Le crédit est réel, la réduction ne l'est pas. | W18: Revue de 25 ans de projets forestiers : majorité jugée non additionnelle. Marché volontaire en baisse de plus de 60 % depuis 2022. | X18: Le prix est le signal : une tonne réellement évitée ne coûte pas trois euros. Le crédit est réel, la réduction sous-jacente rarement additionnelle. | Y18: Noyau · Piège — le piège n°1, documenté, marché effondré de plus de 60 %
A19: A25 | B19: Actif | C19: Économique | D19: Désinvestissement institutionnel | E19: vendre pour l'exemple | F19: Mondial | H19: 2 | L19: 1 | N19: 100 | O19: Facile à annuler | P19: Contestée | Q19: T46 | R19: oui | T19: 2 | U19: Perçu +9 partout. Contrainte +1 seulement : le signal est réel, l'effet sur le coût du capital ne l'est pas. | V19: Vendre un titre ne retire pas un euro à l'entreprise : il change de porteur au prix du marché. L'effet passe par la stigmatisation et par le signal donné aux autres investisseurs. | W19: Mouvement de désinvestissement depuis 2012 ; exclusions du fonds souverain norvégien. Les travaux empiriques ne mettent pas en évidence d'effet mesurable sur le coût du capital des majors. | X19: Le titre vendu est racheté, souvent par un acteur moins exposé à la pression publique. Le levier déplace la propriété, pas les émissions — et il consomme le capital qui aurait financé une contrainte réelle. | Y19: Extension · robustesse contestée — candidat sérieux au statut de PIÈGE plutôt que de levier
A20: A26 | B20: Actif | C20: Technologique | D20: Programme nucléaire accéléré | F20: Bloc | H20: 5 | L20: 3 | N20: 100 | O20: Difficile à annuler | P20: Faible | Q20: A46 | R20: oui | T20: 1 | U20: Contrainte +3 et plafond −6 : le budget part, la centrale arrive après la partie. | V20: Le levier est réel sur l'horizon long. Présenté comme réponse à la décennie, il sert d'argument de report. | W20: Délais de douze à dix-sept ans par réacteur ; Flamanville, douze ans de retard. | X20: Le programme est légitime sur l'horizon long — voir A46. Présenté comme réponse à la décennie, il mobilise un budget aujourd'hui pour une production qui arrive après la partie. | Y20: Noyau · Piège — le levier nucléaire est réel (A46), c'est le CALENDRIER qui est le piège. Évite que le jeu soit lu comme antinucléaire
A21: A27 | B21: Actif | C21: Économique | D21: Retrait de l'assurance sur les projets fossiles | E21: boycott financier | F21: Mondial | H21: 2 | L21: 2 | N21: 100 | O21: Facile à annuler | P21: Moyenne | Q21: T74 | T21: 4 | U21: Contrainte +7 sur les cinq blocs à rente fossile élevée (AN, AS, GR, AL, AF). Un projet non assurable ne se finance pas. | V21: Sans couverture, aucune banque ne prête. Le verrou est privé, donc hors de portée du législateur adverse. | W21: Retraits successifs des réassureurs sur le charbon et les sables bitumineux depuis 2017. | X21: Des assureurs de second rang et des captives publiques prennent le relais dans les blocs à rente élevée. | Y21: Noyau · Verrou — un projet non assurable ne se finance pas ; branche sur la mécanique de retrait assurantiel
A22: A28 | B22: Actif | C22: Économique | D22: Suppression des niches fiscales sectorielles | E22: la fin des privilèges | F22: Bloc | G22: 3 | K22: 40 | L22: 2 | N22: 100 | O22: Facile à annuler | P22: Élevée | Q22: T41 | T22: 3 | U22: Contrainte +13 et friction +18. Friction portée à +26 si le bloc a déjà subi une campagne territoriale. | V22: Kérosène, gazole non routier, exonérations sectorielles : le gain budgétaire est immédiat et la cible est étroite, donc parfaitement organisée pour se défendre. | W22: Suppression progressive de l'exonération sur le gazole non routier agricole annoncée en France fin 2023, retirée en février 2024 après la mobilisation. | X22: Une niche défendue par une profession identifiable produit une fracture professionnelle, pas une contestation diffuse : elle est plus violente et plus courte. | Y22: Extension · déclenche la fracture professionnelle (paire avec T41) — à réintégrer tôt
A23: A29 | B23: Actif | C23: International | D23: Financement climat Nord-Sud | E23: chèque en blanc | F23: Mondial | H23: 5 | L23: 1 | N23: 100 | O23: Facile à annuler | P23: Moyenne | Q23: T02 | S23: Confiance multilatérale (avec A65) | T23: 4 | U23: Contrainte +10 et perçu +6 sur l'Inde, l'Afrique, l'Amérique latine et le reste de l'Asie. | V23: Le capital est le facteur limitant des blocs émergents, pas la volonté. Le financement lève directement la contrainte. | W23: 100 Md$/an promis en 2009, atteints en 2022 ; nouvel objectif de 300 Md$/an acté à Bakou en 2024. | X23: Sans lui, aucun accord mondial ne tient. Avec lui, la facture est visible chez vous et invisible ailleurs. | Y23: Noyau · Coalition — sans lui aucun accord mondial ne tient ; contre de T02
A24: A31 | B24: Actif | C24: Économique | D24: Redistribution du produit de la taxe | E24: redistribution électoraliste | F24: Bloc | H24: 3 | L24: 1 | M24: une tarification carbone en vigueur — sans produit, il n'y a rien à redistribuer | N24: 100 | O24: Facile à annuler | P24: Élevée | Q24: T08 | S24: Le chèque avec la taxe (avec A01) | T24: 4 | U24: Friction −26 et compensation durable installée sur le bloc. | V24: Rendre le produit sous forme de chèque visible transforme un impôt en transfert. La mesure survit à l'alternance. | W24: Dividende carbone canadien, chèque trimestriel identifiable. Absence de redistribution lisible en France en 2018. | X24: Carte ennuyeuse et décisive : sans elle, la tarification ne passe pas deux tours. | Y24: Noyau · Coalition — carte ennuyeuse et décisive. Sans elle, A01 ne survit pas à T39
A25: A33 | B25: Actif | C25: Judiciaire | D25: Contentieux climatique contre l'État | E25: gouvernement des juges | F25: Bloc | H25: 2 | L25: 1 | N25: 72 | O25: Difficile à annuler | P25: Élevée | Q25: T26 | T25: 4 | U25: Contrainte +12 sans condition de soutien perçu. Sans effet en régime autoritaire. | V25: Contourne l'arène électorale : le juge impose ce que la majorité ne vote pas. Le seul levier qui ignore la jauge d'opinion. | W25: Urgenda (Pays-Bas, 2019), Affaire du Siècle (France, 2021), Neubauer (Allemagne, 2021). | X25: Gagner un procès n'exécute rien : l'État condamné peut payer et continuer. | Y25: Noyau · Verrou — contourne l'arène électorale par le juge
A26: A35 | B26: Actif | C26: Judiciaire | D26: Recours devant une cour régionale des droits humains | E26: juges étrangers | F26: Mondial | H26: 3 | J26: 1 | L26: 2 | M26: un contentieux national déjà porté — on ne saisit pas la cour régionale d'emblée | N26: 58 | O26: Irréversible | P26: Élevée | Q26: T24 | T26: 4 | U26: Contrainte +9 au tour suivant sur tous les blocs démocratiques. | V26: Crée une obligation opposable à tous les États membres d'un seul coup, sans passer par aucun parlement. | W26: CEDH, KlimaSeniorinnen contre Suisse, avril 2024 : première condamnation d'un État pour inaction climatique par une cour des droits humains. | X26: Ne touche que les blocs soumis à la juridiction. Les plus gros émetteurs n'y sont pas. | Y26: Pilier · Verrou — irréversible, multi-bloc d'un seul coup (KlimaSeniorinnen 2024)
A27: A36 | B27: Actif | C27: Judiciaire | D27: Avis consultatif de juridiction internationale | E27: droit mou international | F27: Mondial | G27: 3 | J27: 2 | L27: 3 | M27: un contentieux climatique déjà engagé | N27: 52 | O27: Irréversible | P27: Élevée | Q27: T24 | S27: La sortie par le droit (avec A71) | T27: 4 | U27: Contrainte +6 partout dans deux tours. Neutralise l'arbitrage investisseur-État pendant deux tours. | V27: Établit que les obligations climatiques relèvent du droit international général : toutes les procédures suivantes s'y adossent. | W27: Avis consultatif de la Cour internationale de justice sur les obligations des États, 23 juillet 2025. | X27: Non contraignant en lui-même. Sa force est entièrement dans ce que les juges nationaux en font ensuite. | Y27: Pilier · Verrou — irréversible mondial, ouvre la voie aux réparations (CIJ 2025)
A28: A37 | B28: Actif | C28: Judiciaire | D28: Contentieux publicité mensongère | E28: police de la parole | F28: Bloc | G28: 2 | H28: 1 | L28: 2 | N28: 66 | O28: Difficile à annuler | P28: Élevée | Q28: T26 | S28: Le dossier et le procès (avec A54) | T28: 2 | U28: Retire l'emprise médiatique installée sur le bloc et rend 10 de soutien perçu. Sans emprise à défaire, l'action ne rend que 4. Crédibilité adverse −6. | V28: Une campagne qui présente une activité fossile comme neutre en carbone est une allégation commerciale, pas une opinion. Elle se juge sur la preuve, et la preuve manque. | W28: Décisions de l'ASA britannique contre des campagnes pétrolières ; plainte française contre TotalEnergies pour pratiques commerciales trompeuses, 2022. | X28: Le retrait de la campagne arrive après qu'elle a produit son effet. Le procès défait l'emprise, il ne rend pas les tours perdus. | Y28: Extension · redondant avec A17 dans le noyau
A29: A38 | B29: Actif | C29: Technologique | D29: Captage et stockage sur centrale électrique | F29: Bloc | H29: 5 | J29: 2 | L29: 2 | N29: 100 | O29: Difficile à annuler | P29: Faible | Q29: A20 | R29: oui | T29: 1 | U29: Contrainte +4 dans deux tours, pour un coût de 5. Prolonge le parc fossile. | V29: Techniquement possible, économiquement absurde face au renouvelable : on paie deux fois pour produire la même électricité. | W29: Boundary Dam et Petra Nova : taux de captage réels très inférieurs aux annonces, arrêts prolongés. | X29: La même technologie est défendable sur le ciment et la chimie, où la réaction elle-même émet — voir A44. Sur une centrale, elle revient à payer deux fois pour la même électricité. | Y29: Noyau · Piège — pendant piège de A44 : même technologie, un usage légitime, un usage piège
A30: A39 | B30: Actif | C30: Technologique | D30: R&D publique | F30: Bloc | H30: 3 | J30: 3 | L30: 1 | N30: 100 | O30: Difficile à annuler | P30: Moyenne | Q30: T68 | T30: 2 | U30: Indice technologique +14 dans trois tours. Aucun effet immédiat. | V30: Prépare les leviers des tours suivants. Le seul levier dont le rendement est entièrement reporté. | W30: Mission Innovation lancée en 2015 en marge de la COP21 ; budgets publics de R&D énergie. | X30: Ne remplace jamais le déploiement : chercher sans déployer ne fait pas baisser les prix. | Y30: Noyau · Émissions — PROMU : contre de T04 (optimisme technologique), et seule carte qui enseigne la latence pure
A31: A40 | B31: Actif | C31: Technologique | D31: Électrification des usages | E31: tout-électrique forcé | F31: Bloc | H31: 3 | K31: 40 | L31: 2 | M31: le réseau électrique et le stockage — prérequis physique de l'électrification | N31: 100 | O31: Difficile à annuler | P31: Élevée | Q31: A42 | S31: La courbe s'effondre (avec A18) | T31: 5 | U31: Contrainte +16, augmentée par l'indice technologique. Friction +5. | V31: Un moteur électrique convertit trois à quatre fois mieux qu'un moteur thermique. Le gain est physique, avant même de décarboner le mix. | W31: Ventes de voitures électriques passées de 1 % à plus de 20 % du marché mondial entre 2015 et 2024. | X31: Sature si le réseau n'a pas été renforcé. Ciblée par les faux vecteurs alternatifs. | Y31: Noyau · Émissions — multiplicateur de toute décarbonation du mix (puissance 5)
A32: A41 | B32: Actif | C32: Économique | D32: Plan de sobriété organisée | E32: rationnement déguisé | F32: Bloc | G32: 2 | L32: 2 | N32: 100 | O32: Facile à annuler | P32: Moyenne | Q32: T09 | T32: 3 | U32: Contrainte +9 dès ce tour, friction +5, perçu +3. Le seul levier actif dont l'effet tombe entièrement dans le tour. | V32: Consignes de température, décalage des usages, pilotage de la pointe. Ce n'est pas de la contrainte individuelle mais du pilotage administratif d'une consommation collective. | W32: Plan de sobriété français de l'hiver 2022 : environ 12 % de consommation de gaz en moins à conditions climatiques corrigées, sans coupure. | X32: L'effet ne survit pas à la campagne qui le porte. Sans mesure structurelle derrière, la consommation revient à son niveau en deux ans. | Y32: Extension · effet immédiat rare côté actif — à réintégrer si l'équilibrage montre l'actif trop lent
A33: A42 | B33: Actif | C33: Technologique | D33: Hydrogène pour la voiture particulière | F33: Bloc | H33: 4 | J33: 2 | L33: 2 | N33: 100 | O33: Difficile à annuler | P33: Faible | Q33: A40 | R33: oui | T33: 1 | U33: Contrainte +3 dans deux tours, pour un coût de 4. Retarde l'électrification directe. | V33: Rendement global trois à quatre fois inférieur à la batterie : électrolyse, compression, pile à combustible, chaque étape perd. | W33: Abandons successifs des programmes hydrogène automobile depuis 2020 ; parc mondial resté marginal. | X33: Le même vecteur est pertinent là où l'électrification directe est impossible — industrie, maritime, voir A47. Sur la voiture particulière, il coûte trois à quatre fois plus d'électricité pour le même kilomètre. | Y33: Noyau · Piège — rendement 3 à 4 fois inférieur à l'électrique à batterie. Pendant piège de A47
A34: A43 | B34: Actif | C34: Technologique | D34: Carburants de synthèse pour l'automobile | F34: Bloc | H34: 4 | L34: 3 | N34: 100 | O34: Difficile à annuler | P34: Faible | Q34: A04 | R34: oui | T34: 1 | U34: Contrainte +2 et plafond −8 : ouvre une exemption réglementaire durable. | V34: Coût et rendement prohibitifs à l'échelle. Sert surtout à maintenir légalement le moteur thermique. | W34: Exemption e-fuels obtenue en 2023 sur le règlement européen de fin du thermique en 2035. | X34: Le coût et le rendement restent prohibitifs à l'échelle du parc automobile. Dans les faits, la filière a surtout servi à obtenir une exemption au règlement de 2035. | Y34: Noyau · Piège — devient une exemption réglementaire réelle (paire avec T52)
A35: A44 | B35: Actif | C35: Technologique | D35: Captage sur émissions industrielles | F35: Bloc | H35: 5 | K35: 30 | L35: 3 | N35: 100 | O35: Difficile à annuler | P35: Contestée | Q35: T69 | T35: 2 | U35: Contrainte +8 seulement, sans friction. Utile là où rien d'autre n'existe. | V35: Ciment et chimie émettent par la réaction elle-même, pas par la combustion : l'électrification n'y peut rien. | W35: Sous-performance documentée de Boundary Dam et Petra Nova, taux de captage réels inférieurs aux annonces. | X35: La même technologie appliquée à la production électrique produit l'effet inverse : elle prolonge le parc fossile au lieu de traiter des émissions qu'aucune autre technique ne réduit. | Y35: Extension · paire pédagogique avec le piège P07 — réintégrer avec P07 ou pas du tout
A36: A46 | B36: Actif | C36: Technologique | D36: Programme nucléaire | F36: Bloc | H36: 5 | J36: 3 | L36: 2 | N36: 100 | O36: Difficile à annuler | P36: Élevée | Q36: T72 | T36: 3 | U36: Contrainte +15 dans trois tours, friction +8 immédiate. | V36: Effet réel et durable sur le mix, avec un délai de douze à dix-sept ans par réacteur. Le calendrier est le sujet, pas la technologie. | W36: Relance EPR2 en France (2022) ; dérives de Flamanville et Hinkley Point C. | X36: Fracture la coalition écologiste. Et le même programme, présenté comme une réponse à l'échéance de 2030 plutôt qu'à celle de 2050, sert d'argument à repousser tout le reste : la technologie est honnête, le calendrier qu'on lui prête ne l'est pas toujours. | Y36: Signature — fracture la coalition écologiste. Arme à double tranchant, incontournable en contexte français. Paire avec le piège P10
A37: A47 | B37: Actif | C37: Technologique | D37: Hydrogène pour l'industrie et le maritime | F37: Bloc | H37: 5 | J37: 2 | L37: 3 | M37: le réseau électrique, ou un indice technologique d'au moins 25 | N37: 100 | O37: Difficile à annuler | P37: Contestée | Q37: T69 | T37: 2 | U37: Contrainte +9 dans deux tours. | V37: Pertinent là où l'électrification directe est impossible : acier, ammoniac, navires longue distance. | W37: Stratégies hydrogène européennes et nationales depuis 2020, révisées à la baisse en 2024-2025. | X37: Le même vecteur appliqué à la voiture particulière perd les trois quarts de l'énergie en conversions successives, là où la batterie fait le trajet directement. | Y37: Extension · paire pédagogique avec le piège P04 — réintégrer avec P04 ou pas du tout
A38: A48 | B38: Actif | C38: Réglementaire | D38: Réduction des émissions agricoles | E38: agribashing | F38: Bloc | G38: 5 | K38: 50 | L38: 2 | N38: 56 | O38: Facile à annuler | P38: Moyenne | Q38: T41 | T38: 4 | U38: Contrainte +13, friction +20. Le secteur le plus verrouillé politiquement. | V38: Méthane entérique, fertilisation azotée, cheptel. Un cinquième des émissions mondiales, presque jamais contraint. | W38: Objectifs agricoles retirés du Pacte vert européen après les mobilisations de 2024. | X38: Déclenche mécaniquement la fracturation de la coalition : c'est le levier préféré de l'adversaire pour détacher un groupe social. | Y38: Noyau · Émissions — le secteur le plus verrouillé politiquement ; paire avec T41
A39: A49 | B39: Actif | C39: Narratif | D39: Attribution rapide d'un événement extrême | E39: science militante | F39: Mondial | I39: 2 | L39: 1 | N39: 100 | O39: Facile à annuler | P39: Élevée | Q39: T36 | S39: Fenêtre d'attention (avec A50) | T39: 3 | U39: Perçu +10 sur le bloc frappé, +4 ailleurs. Immunise contre la saturation ce tour-ci. | V39: Sans étude d'attribution, une catastrophe reste un fait divers météorologique. Avec, elle devient une conséquence datée et chiffrée. | W39: World Weather Attribution publie des études en quelques jours depuis 2015 ; canicule européenne de 2022 rendue au moins dix fois plus probable. | X39: La fenêtre se referme en une semaine. Jouée trop tard, la carte ne déplace plus rien. | Y39: Pilier · Opinion — mécanique centrale d'attribution. Sans elle, aucune catastrophe ne déplace de jauge
A40: A50 | B40: Actif | C40: Narratif | D40: Révéler la majorité silencieuse | E40: sondage militant | F40: Bloc | I40: 2 | L40: 1 | N40: 100 | O40: Facile à annuler | P40: Élevée | Q40: T33 | S40: Fenêtre d'attention (avec A49) | T40: 4 | U40: Le perçu rattrape 60 % de son écart avec le soutien réel. Deux usages par partie. | V40: Les gens sous-estiment massivement le soutien des autres et se taisent en conséquence. Publier le chiffre réel casse la spirale du silence. | W40: Andre et al., Nature Climate Change 2024 : 69 % de soutien réel pour 43 % de soutien perçu, dans 125 pays. | X40: Ne crée rien : ne fait que révéler ce qui existe déjà. Sur un bloc au soutien réel faible, elle ne sert à rien. | Y40: Pilier · Opinion — mécanique signature du jeu (écart 69 % réel / 43 % perçu). Usage limité par partie
...

Sheet Non retenus
A1: ID catalogue | B1: Camp | C1: Famille | D1: Levier | E1: Puissance réelle | F1: Verdict août 2026 | G1: Motif d'août | H1: Verdict v0.9.1 | I1: Pourquoi | J1: Ancrage réel daté
A2: A06 | B2: Actif | C2: Réglementaire | D2: Norme bâtiment / interdiction des passoires | E2: 3 | F2: À tester | G2: Extension · à garder si la friction propriétaire est modélisée (absorbe A09) | H2: Écarté — pas de décision distincte | I2: Défendable, mais n'ouvre aucun choix que le jeu ne propose autrement. | J2: Calendrier DPE FR : classe G en 2025, F en 2028
A3: A08 | B3: Actif | C3: Réglementaire | D3: Plafond d'émission des centrales | E3: 4 | F3: À tester | G3: Extension · recouvre partiellement A02 et A05 — vérifier qu'il apporte une décision distincte | H3: Écarté — redondance | I3: Le jeu produit déjà la même décision par une autre carte. | J3: Clean Power Plan US 2015, annulé en 2019 puis remplacé — exemple d'annulabilité
A4: A09 | B4: Actif | C4: Réglementaire | D4: Obligation de rénovation énergétique | E4: 3 | F4: Écarté | G4: Fusionné dans A06 (norme bâtiment) — même effet, même friction, deux cartes redondantes | H4: Écarté — fusionné en août | I4: Fusion décidée le 17 août 2026 et maintenue : voir le motif d'origine. | J4: Directive UE performance énergétique des bâtiments, révisée 2024
A5: A13 | B5: Actif | C5: Réglementaire | D5: Zone à faibles émissions | E5: 2 | F5: À tester | G5: Extension · portée locale : n'existe mécaniquement que si le jeu descend sous le bloc | H5: Écarté — hors échelle | I5: Portée locale : n'existe mécaniquement que si le jeu descend sous le bloc, ce qu'il ne fait pas. | J5: ZFE françaises ; ULEZ Londres 2023 et son coût électoral
A6: A14 | B6: Actif | C6: Réglementaire | D6: Planification urbaine et fin de l'étalement | E6: 4 | F6: À tester | G6: Extension · horizon trop long pour 8 à 20 tours — chercher une représentation lisible | H6: Écarté — pas de décision distincte | I6: Défendable, mais n'ouvre aucun choix que le jeu ne propose autrement. | J6: Objectif ZAN français ; politiques de densification
A7: A16 | B7: Actif | C7: Réglementaire | D7: Devoir de vigilance sur la chaîne de valeur | E7: 3 | F7: Écarté | G7: Fusionné dans A15 (reporting) — même famille, même contre-levier T20 | H7: Écarté — fusionné en août | I7: Fusion décidée le 17 août 2026 et maintenue : voir le motif d'origine. | J7: Loi FR 2017 ; directive CSDDD UE 2024, périmètre réduit en 2025
A8: A23 | B8: Actif | C8: Économique | D8: Verdissement de la banque centrale | E8: 3 | F8: À tester | G8: Extension · technocratique, hors du champ électoral : tester si le joueur comprend l'effet | H8: Écarté — pas de décision distincte | I8: Défendable, mais n'ouvre aucun choix que le jeu ne propose autrement. | J8: Verdissement du portefeuille d'obligations d'entreprises de la BCE, 2022
A9: A24 | B9: Actif | C9: Économique | D9: Exigences prudentielles et stress tests climat | E9: 3 | F9: Écarté | G9: Fusionné dans A23 (banque centrale) — encore moins lisible pour le joueur | H9: Écarté — fusionné en août | I9: Fusion décidée le 17 août 2026 et maintenue : voir le motif d'origine. | J9: Stress tests climatiques BCE 2022 ; travaux du NGFS
A10: A30 | B10: Actif | C10: Économique | D10: Partenariat de transition juste (JETP) | E10: 2 | F10: Écarté | G10: Fusionné dans A29 (financement Nord-Sud) — décaissements réels trop faibles pour justifier une carte propre | H10: Écarté — fusionné en août | I10: Fusion décidée le 17 août 2026 et maintenue : voir le motif d'origine. | J10: JETP Afrique du Sud 2021, Indonésie et Vietnam 2022 : décaissements lents
A11: A32 | B11: Actif | C11: Économique | D11: Commande publique verte | E11: 3 | F11: À tester | G11: Extension · 10 à 15 % du PIB, très peu exploité dans le réel : gisement de jeu, effet difficile à chiffrer | H11: Écarté — pas de décision distincte | I11: Défendable, mais n'ouvre aucun choix que le jeu ne propose autrement. | J11: Buy Clean californien ; clauses carbone des marchés publics UE
A12: A34 | B12: Actif | C12: Judiciaire | D12: Contentieux contre une entreprise | E12: 3 | F12: À tester | G12: Extension · gain infirmé en appel (Shell, 2024) — modéliser la fragilité plutôt que le gain | H12: Écarté — redondance | I12: Le jeu produit déjà la même décision par une autre carte. | J12: Milieudefensie c. Shell : -45 % ordonné en 2021, infirmé en appel en 2024
A13: A42 | B13: Actif | C13: Technologique | D13: Efficacité matière et économie circulaire | E13: 3 | F13: À tester | G13: Extension · angle mort réel des politiques, difficile à modéliser | H13: Non construit — identifiant occupé | I13: Efficacité matière et économie circulaire : non construit, et l'identifiant A42 désigne un piège dans le jeu. | J13: Travaux du Shift Project sur l'industrie ; référentiels ADEME
... A35: T47 | B35: Attentiste | C35: Économique | D35: Rachat d'actions plutôt qu'investissement | E35: 3 | F35: À tester | G35: Extension · retire du capital du jeu plutôt que de le transformer | H35: Écarté — redondance | I35: Le jeu produit déjà la même décision par une autre carte. | J35: Records de rachats d'actions des majors pétrolières en 2022-2023

Sheet Correspondance
A1: ID catalogue | B1: ID dans le jeu | C1: Levier | D1: Pourquoi l'identifiant a changé
A2: P01 | B2: A22 | C2: Compensation carbone volontaire | D2: Piège renuméroté dans la série A en v0.5 : un identifiant commençant par P annonçait le piège au joueur.
A3: P04 | B3: A42 | C3: Hydrogène pour la voiture particulière | D3: idem
A4: P05 | B4: A43 | C4: Carburants de synthèse pour l'automobile | D4: idem
A5: P07 | B5: A38 | C5: Captage et stockage sur centrale électrique | D5: idem
A6: P08 | B6: A09 | C6: Objectif net zéro 2050 | D6: idem
A7: P10 | B7: A26 | C7: Programme nucléaire accéléré | D7: idem
A8: A38 | B8: A70 | C8: Contentieux en responsabilité fondé sur l'attribution | D8: Intégré en v0.9 ; l'identifiant A38 était déjà pris par le piège ex-P07.
A9: A22 | B9: A73 | C9: Fin du financement public à l'export des fossiles | D9: Intégré en v0.9.1 ; l'identifiant A22 était déjà pris par le piège ex-P01.
A10: P09 | B10: T68 | C10: Géo-ingénierie solaire à l'étude | D10: Écrit en v0.7 comme levier attentiste plutôt que comme piège.
A11: T14 | B11: T62 | C11: Financement de campagne | D11: Recouvert par T62, écrit en v0.7 : même ancrage, mécanique plus nette.
A12: A26 | B12: — | C12: Actionnariat actif et résolutions climat | D12: Devenu un événement du jeu en v0.9 : non reproductible à volonté.
... A14: P11 | B14: — | C14: Sommet international sans mécanisme contraignant | D14: Était déjà un événement du jeu depuis l'origine (Sommet international).
A16: Six identifiants de la série A désignent, dans le jeu, un piège différent du levier qu'ils nomment dans le catalogue d'août. Toute lecture croisée des deux fichiers doit passer par cette table.

Sheet Contrôles
A1: Contrôles du catalogue
A2: Colonne B : formule, recalculée à l'ouverture du fichier. Colonne C : la même valeur au moment de la génération.
A3: Les deux colonnes doivent coïncider. Un écart signale que le catalogue a été édité à la main depuis sa génération.
A5: Répartition par camp
A7: Actif | B7: =COUNTIF(Catalogue!$B$2:$B$113,"Actif") | C7: 57
A8: Attentiste | B8: =COUNTIF(Catalogue!$B$2:$B$113,"Attentiste") | C8: 55
A9: dont pièges | B9: =COUNTIF(Catalogue!$R$2:$R$113,"oui") | C9: 8
A10: Total des leviers | B10: =COUNTA(Catalogue!$A$2:$A$113) | C10: 112
A12: Répartition par famille
A14: Discours — Attentiste | B14: =COUNTIFS(Catalogue!$C$2:$C$113,"Discours",Catalogue!$B$2:$B$113,"Attentiste") | C14: 8
A15: Institutionnel — Attentiste | B15: =COUNTIFS(Catalogue!$C$2:$C$113,"Institutionnel",Catalogue!$B$2:$B$113,"Attentiste") | C15: 7
A16: International — Actif | B16: =COUNTIFS(Catalogue!$C$2:$C$113,"International",Catalogue!$B$2:$B$113,"Actif") | C16: 5
A17: International — Attentiste | B17: =COUNTIFS(Catalogue!$C$2:$C$113,"International",Catalogue!$B$2:$B$113,"Attentiste") | C17: 6
A18: Judiciaire — Actif | B18: =COUNTIFS(Catalogue!$C$2:$C$113,"Judiciaire",Catalogue!$B$2:$B$113,"Actif") | C18: 5
A19: Judiciaire — Attentiste | B19: =COUNTIFS(Catalogue!$C$2:$C$113,"Judiciaire",Catalogue!$B$2:$B$113,"Attentiste") | C19: 5
A20: Narratif — Actif | B20: =COUNTIFS(Catalogue!$C$2:$C$113,"Narratif",Catalogue!$B$2:$B$113,"Actif") | C20: 8
A21: Narratif — Attentiste | B21: =COUNTIFS(Catalogue!$C$2:$C$113,"Narratif",Catalogue!$B$2:$B$113,"Attentiste") | C21: 8
A22: Réglementaire — Actif | B22: =COUNTIFS(Catalogue!$C$2:$C$113,"Réglementaire",Catalogue!$B$2:$B$113,"Actif") | C22: 13
A23: Réglementaire — Attentiste | B23: =COUNTIFS(Catalogue!$C$2:$C$113,"Réglementaire",Catalogue!$B$2:$B$113,"Attentiste") | C23: 3
A24: Technologique — Actif | B24: =COUNTIFS(Catalogue!$C$2:$C$113,"Technologique",Catalogue!$B$2:$B$113,"Actif") | C24: 10
A25: Technologique — Attentiste | B25: =COUNTIFS(Catalogue!$C$2:$C$113,"Technologique",Catalogue!$B$2:$B$113,"Attentiste") | C25: 4
A26: Économique — Actif | B26: =COUNTIFS(Catalogue!$C$2:$C$113,"Économique",Catalogue!$B$2:$B$113,"Actif") | C26: 10
A27: Économique — Attentiste | B27: =COUNTIFS(Catalogue!$C$2:$C$113,"Économique",Catalogue!$B$2:$B$113,"Attentiste") | C27: 10
A28: Électoral — Actif | B28: =COUNTIFS(Catalogue!$C$2:$C$113,"Électoral",Catalogue!$B$2:$B$113,"Actif") | C28: 6
A29: Électoral — Attentiste | B29: =COUNTIFS(Catalogue!$C$2:$C$113,"Électoral",Catalogue!$B$2:$B$113,"Attentiste") | C29: 4
A31: Ouverture par époque
A33: Époque 1 — à partir de 2015 | B33: =COUNTIF(Catalogue!$L$2:$L$113,1) | C33: 49
A34: Époque 2 — à partir de 2035 | B34: =COUNTIF(Catalogue!$L$2:$L$113,2) | C34: 39
A35: Époque 3 — à partir de 2055 | B35: =COUNTIF(Catalogue!$L$2:$L$113,3) | C35: 24
A37: Cohérence des contre-leviers
A39: Leviers sans contre-levier désigné | B39: =COUNTBLANK(Catalogue!$Q$2:$Q$113) | C39: 2 | D39: Sans contre : A71, T38
A40: Contre-leviers pointant hors du jeu | B40: 0 | C40: 0 | D40: Orphelins : aucun — vérifié en Python, aucune formule ne peut le faire.
A42: Puissance réelle (colonne à remplir)
A44: Leviers dont la puissance a été estimée en août | B44: =COUNT(Catalogue!$T$2:$T$113) | C44: 97
A45: Leviers sans estimation (cellules jaunes) | B45: =112-COUNT(Catalogue!$T$2:$T$113) | C45: 15
A46: Puissance moyenne — Actif | B46: =ROUND(AVERAGEIFS(Catalogue!$T$2:$T$113,Catalogue!$B$2:$B$113,"Actif"),2) | C46: 3.27 | D46: L'asymétrie du catalogue d'août est-elle conservée ?
A47: Puissance moyenne — Attentiste | B47: =ROUND(AVERAGEIFS(Catalogue!$T$2:$T$113,Catalogue!$B$2:$B$113,"Attentiste"),2) | C47: 4.14
A49: Leviers du catalogue jamais construits
A51: Total | B51: =COUNTA('Non retenus'!$A$2:$A$200) | C51: 34 | D51: Chacun porte un verdict dans l'onglet Non retenus : aucun n'est laissé en suspens.
