Workbook

Sheet Proposition
B2: HEAT — Proposition de sélection v1
B3: 17 août 2026 — 134 leviers arbitrés : 75 retenus, 43 à tester, 16 écartés
B5: Comment lire
B6: Onglet Catalogue : les 134 leviers, colonne Verdict pré-remplie et colonne Motif expliquant chaque arbitrage.
B7: Onglet Noyau : les 75 retenus, regroupés par fonction dans la boucle de jeu.
B8: Onglet Contrôles : cohérence des contre-leviers, répartition, trous de couverture assumés.
B9: Rien n'est figé : la colonne Verdict reste modifiable, l'onglet Contrôles se recalcule.
B11: Règles d'arbitrage appliquées
B12: 1. Un levier ne survit que s'il produit une DÉCISION distincte. Deux cartes au même effet = une carte.
B13: 2. Un levier retenu doit avoir son contre-levier retenu, sinon il est imblocable ou inutile.
B14: 3. Pas de carte sans ancrage réel daté. C'est la règle qui protège le jeu de l'accusation de propagande.
B15: 4. Les pièges retenus vont par paire avec leur pendant légitime (A44/P07, A47/P04, A46/P10).
... B28: (retrait de l'assurance) n'a pas de contre direct dans le noyau. Voir l'onglet Contrôles.

Sheet Catalogue
A1: ID | B1: Camp | C1: Famille | D1: Levier | E1: Effet dans le jeu | F1: Ancrage réel (daté) | G1: Latence | H1: Ressource consommée | I1: Coût (1-5) | J1: Puissance réelle (1-5) | K1: Portée | L1: Réversibilité | M1: Robustesse des preuves | N1: Difficulté mini (1-4) | O1: Contre-levier | P1: Verdict | Q1: Motif / rôle dans le jeu
A2: A01 | B2: Actif | C2: Réglementaire | D2: Tarification carbone nationale | E2: Réduit les émissions du bloc tant qu'elle tient. Génère une friction forte si non redistribuée. | F2: Taxe carbone FR 2014-2018, gelée après les Gilets jaunes (déc. 2018) | G2: Court (1-2 tours) | H2: Capital politique | I2: 4 | J2: 4 | K2: Bloc | L2: Facile à annuler | M2: Élevée | N2: 1 | O2: T39 | P2: Retenu | Q2: Noyau · Émissions — la tarification icônique, et le générateur de friction du jeu (paire avec A31)
A3: A02 | B3: Actif | C3: Réglementaire | D3: Marché de quotas (ETS) | E3: Plafond décroissant + échange. Effet croissant, friction citoyenne faible car indirecte. | F3: EU ETS depuis 2005 ; ETS2 bâtiment/transport prévu 2027 | G3: Moyen (3-5 tours) | H3: Capital politique | I3: 3 | J3: 4 | K3: Bloc | L3: Difficile à annuler | M3: Élevée | N3: 2 | O3: T22 | P3: Retenu | Q3: Noyau · Émissions — l'outil de fond, plafond décroissant, faible friction citoyenne
A4: A03 | B4: Actif | C4: Réglementaire | D4: Ajustement carbone aux frontières | E4: Neutralise la fuite de carbone et désamorce le whataboutisme. Provoque des représailles commerciales. | F4: MACF/CBAM UE : déclaratif 2023, financier 2026 | G4: Moyen (3-5 tours) | H4: Capital politique | I4: 4 | J4: 3 | K4: Bloc | L4: Difficile à annuler | M4: Moyenne | N4: 3 | O4: T45 | P4: Retenu | Q4: Noyau · Émissions — contre structurel du whataboutisme (T02) et de la fuite de carbone (T53)
A5: A04 | B5: Actif | C5: Réglementaire | D5: Norme d'émission véhicules | E5: Contraint les constructeurs sans coût budgétaire. Très efficace et quasi invisible du citoyen. | F5: Règlement UE 95 gCO2/km ; fin du thermique neuf 2035 | G5: Moyen (3-5 tours) | H5: Capital politique | I5: 2 | J5: 4 | K5: Bloc | L5: Difficile à annuler | M5: Élevée | N5: 1 | O5: T52 | P5: Retenu | Q5: Noyau · Émissions — contrainte industrielle sans coût budgétaire ; contre direct de T52
A6: A05 | B6: Actif | C6: Réglementaire | D6: Interdiction de vente datée | E6: Date butoir sur une technologie. Déclenche l'anticipation industrielle dès l'annonce, avant tout effet réel. | F6: Fin des chaudières fioul FR 2022 ; thermique UE 2035 | G6: Long (>5 tours) | H6: Capital politique | I6: 4 | J6: 5 | K6: Bloc | L6: Facile à annuler | M6: Élevée | N6: 2 | O6: T25 | P6: Retenu | Q6: Noyau · Émissions — déclenche l'anticipation industrielle dès l'annonce (puissance 5)
A7: A07 | B7: Actif | C7: Réglementaire | D7: Suppression des subventions aux fossiles | E7: Retire le soutien budgétaire direct. Meilleur rapport effet/coût du catalogue, et le plus rarement obtenu. | F7: Engagements G20 depuis 2009 ; subventions explicites toujours de l'ordre de 1 200 Md$/an (FMI) | G7: Court (1-2 tours) | H7: Capital politique | I7: 5 | J7: 5 | K7: Mondial | L7: Facile à annuler | M7: Élevée | N7: 2 | O7: T39 | P7: Retenu | Q7: Noyau · Émissions — meilleur rapport effet/coût du catalogue, portée mondiale
A8: A10 | B8: Actif | C8: Réglementaire | D8: Normes d'efficacité des appareils | E8: Levier le plus discret du catalogue : effet cumulatif important, friction quasi nulle. | F8: Étiquetage énergétique UE, écoconception ; interdiction des ampoules à incandescence | G8: Moyen (3-5 tours) | H8: Capital politique | I8: 1 | J8: 3 | K8: Bloc | L8: Difficile à annuler | M8: Élevée | N8: 1 | O8: — | P8: Retenu | Q8: Noyau · Émissions — le levier invisible : coût 1, aucun contre-levier. Enseigne que l'efficace n'est pas spectaculaire
A9: A11 | B9: Actif | C9: Réglementaire | D9: Réduction obligatoire des fuites de méthane | E9: Meilleur rapport effet/délai du catalogue : le méthane agit en années, pas en siècles. | F9: Global Methane Pledge (2021, 150+ pays) ; règlement méthane UE 2024 | G9: Court (1-2 tours) | H9: Capital politique | I9: 2 | J9: 4 | K9: Multi-bloc | L9: Difficile à annuler | M9: Élevée | N9: 2 | O9: T22 | P9: Retenu | Q9: Noyau · Émissions — le SEUL levier actif à effet rapide. Indispensable à l'équilibrage
A10: A12 | B10: Actif | C10: Réglementaire | D10: Loi-cadre climat à budgets contraignants | E10: Verrouille une trajectoire pluriannuelle et rend chaque écart juridiquement attaquable. | F10: UK Climate Change Act 2008, voté quasi à l'unanimité ; Committee on Climate Change | G10: Long (>5 tours) | H10: Capital politique | I10: 4 | J10: 5 | K10: Bloc | L10: Difficile à annuler | M10: Élevée | N10: 2 | O10: T23 | P10: Retenu | Q10: Pilier · Verrou — budgets pluriannuels contraignants, chaque écart devient attaquable
A11: A15 | B11: Actif | C11: Réglementaire | D11: Reporting extra-financier obligatoire | E11: Rend l'exposition carbone visible des investisseurs. Puissant, mais démontré détricotable. | F11: CSRD UE 2022, largement allégée par l'omnibus de 2025 | G11: Moyen (3-5 tours) | H11: Capital politique | I11: 2 | J11: 3 | K11: Bloc | L11: Facile à annuler | M11: Moyenne | N11: 3 | O11: T20 | P11: Retenu | Q11: Noyau · Verrou — PROMU : contre-levier de quatre cartes du noyau (T05, T20, T51, P01). Charnière de la couche institutionnelle
A12: A17 | B12: Actif | C12: Réglementaire | D12: Interdiction de la publicité fossile | E12: Coupe l'accès du camp adverse à la ressource Attention. Effet indirect mais durable. | F12: Amsterdam 2020 ; loi Climat et Résilience FR 2021 (périmètre restreint) | G12: Moyen (3-5 tours) | H12: Capital politique | I12: 2 | J12: 2 | K12: Bloc | L12: Facile à annuler | M12: Moyenne | N12: 3 | O12: T31 | P12: Retenu | Q12: Signature — le seul levier actif qui attaque directement la ressource Attention adverse
A13: A18 | B13: Actif | C13: Économique | D13: Subvention massive au déploiement | E13: Paye cher pour faire baisser le coût mondial d'une technologie. Bénéficie à tous les blocs, y compris ceux qui n'ont rien payé. | F13: EEG allemand 2000-2015 : ~200 Md€, a amorcé la chute mondiale du prix du PV | G13: Long (>5 tours) | H13: Capital | I13: 5 | J13: 5 | K13: Mondial | L13: Difficile à annuler | M13: Élevée | N13: 1 | O13: — | P13: Retenu | Q13: Noyau · Émissions — courbe d'apprentissage : payé par un bloc, bénéficie à tous. Prouve mécaniquement que l'action marche
... A135: T34 | B135: Attentiste | C135: Narratif | D135: Financement de recherche orientée | E135: Fabrique de l'incertitude scientifique là où il n'y en a plus. Efficacité en baisse depuis 2015. | F135: Financements industriels de travaux sur les coûts de la transition | G135: Long (>5 tours) | H135: Capital | I135: 3 | J135: 2 | K135: Mondial | L135: Difficile à annuler | M135: Élevée | N135: 3 | O135: A58 | P135: Écarté | Q135: Écarté volontairement : reproduire du financement de recherche orientée fabrique du contenu pseudo-scientifique dans le jeu. Risque supérieur au bénéfice

Sheet Noyau
B2: Noyau proposé — 75 leviers
B3: Groupés par fonction dans la boucle de jeu, et non par famille administrative.
B5: Boucle émissions — camp actif (14)
B6: Ce que le joueur actif joue pour faire baisser la courbe
B7: ID | C7: Levier | D7: Latence | E7: Coût | F7: Puiss. | G7: Diff. | H7: Contre | I7: Rôle
B8: A01 | C8: Tarification carbone nationale | D8: Court (1-2 tours) | E8: 4 | F8: 4 | G8: 1 | H8: T39 | I8: la tarification icônique, et le générateur de friction du jeu (paire avec A31)
B9: A02 | C9: Marché de quotas (ETS) | D9: Moyen (3-5 tours) | E9: 3 | F9: 4 | G9: 2 | H9: T22 | I9: l'outil de fond, plafond décroissant, faible friction citoyenne
B10: A03 | C10: Ajustement carbone aux frontières | D10: Moyen (3-5 tours) | E10: 4 | F10: 3 | G10: 3 | H10: T45 | I10: contre structurel du whataboutisme (T02) et de la fuite de carbone (T53)
B11: A04 | C11: Norme d'émission véhicules | D11: Moyen (3-5 tours) | E11: 2 | F11: 4 | G11: 1 | H11: T52 | I11: contrainte industrielle sans coût budgétaire ; contre direct de T52
B12: A05 | C12: Interdiction de vente datée | D12: Long (>5 tours) | E12: 4 | F12: 5 | G12: 2 | H12: T25 | I12: déclenche l'anticipation industrielle dès l'annonce (puissance 5)
B13: A07 | C13: Suppression des subventions aux fossiles | D13: Court (1-2 tours) | E13: 5 | F13: 5 | G13: 2 | H13: T39 | I13: meilleur rapport effet/coût du catalogue, portée mondiale
B14: A10 | C14: Normes d'efficacité des appareils | D14: Moyen (3-5 tours) | E14: 1 | F14: 3 | G14: 1 | H14: — | I14: le levier invisible : coût 1, aucun contre-levier. Enseigne que l'efficace n'est pas spectaculaire
B15: A11 | C15: Réduction obligatoire des fuites de méthane | D15: Court (1-2 tours) | E15: 2 | F15: 4 | G15: 2 | H15: T22 | I15: le SEUL levier actif à effet rapide. Indispensable à l'équilibrage
B16: A18 | C16: Subvention massive au déploiement | D16: Long (>5 tours) | E16: 5 | F16: 5 | G16: 1 | H16: — | I16: courbe d'apprentissage : payé par un bloc, bénéficie à tous. Prouve mécaniquement que l'action marche
B17: A20 | C17: Contrat pour différence / garantie de prix | D17: Moyen (3-5 tours) | E17: 3 | F17: 4 | G17: 2 | H17: — | I17: PROMU : contre du piège P07. C'est le CfD qui rend le CCS sur centrale économiquement absurde
B18: A21 | C18: Investissement réseau et stockage | D18: Long (>5 tours) | E18: 5 | F18: 4 | G18: 2 | H18: — | I18: prérequis physique : sans réseau, les leviers électriques saturent
B19: A39 | C19: R&D publique | D19: Long (>5 tours) | E19: 3 | F19: 2 | G19: 1 | H19: — | I19: PROMU : contre de T04 (optimisme technologique), et seule carte qui enseigne la latence pure
... B21: A48 | C21: Réduction des émissions agricoles | D21: Long (>5 tours) | E21: 5 | F21: 4 | G21: 3 | H21: T41 | I21: le secteur le plus verrouillé politiquement ; paire avec T41
B23: Coalition et friction — camp actif (7)
B24: Ce qu'il joue pour que ses mesures survivent au tour suivant
B25: ID | C25: Levier | D25: Latence | E25: Coût | F25: Puiss. | G25: Diff. | H25: Contre | I25: Rôle
B26: A19 | C26: Politique industrielle verte | D26: Moyen (3-5 tours) | E26: 5 | F26: 4 | G26: 1 | H26: T50 | I26: acheter l'adhésion plutôt que contraindre ; cible du piège T50
B27: A29 | C27: Financement climat Nord-Sud | D27: Moyen (3-5 tours) | E27: 5 | F27: 4 | G27: 2 | H27: T02 | I27: sans lui aucun accord mondial ne tient ; contre de T02
B28: A31 | C28: Redistribution du produit de la taxe carbone | D28: Immédiat | E28: 3 | F28: 4 | G28: 1 | H28: T39 | I28: carte ennuyeuse et décisive. Sans elle, A01 ne survit pas à T39
B29: A59 | C29: Faire du climat un enjeu de campagne | D29: Court (1-2 tours) | E29: 3 | F29: 3 | G29: 1 | H29: T38 | I29: convertit le soutien perçu en mandat ; échoue si la jauge perçue est basse
B30: A60 | C30: Coalition élargie climat + emploi + pouvoir d'achat | D30: Moyen (3-5 tours) | E30: 4 | F30: 4 | G30: 2 | H30: T39 | I30: immunise partiellement contre T39. Coûte cher en concessions
B31: A61 | C31: Ancrage local et réseaux de villes | D31: Moyen (3-5 tours) | E31: 2 | F31: 3 | G31: 2 | H31: T19 | I31: contourne le blocage national ; paire avec T19 (préemption)
B32: A63 | C32: Institution indépendante de suivi | D32: Moyen (3-5 tours) | E32: 2 | F32: 3 | G32: 2 | H32: T21 | I32: rend l'inaction publiquement mesurable à chaque tour
B34: Opinion — camp actif (6)
B35: Les deux jauges : réel lent, perçu volatil
B36: ID | C36: Levier | D36: Latence | E36: Coût | F36: Puiss. | G36: Diff. | H36: Contre | I36: Rôle
B37: A49 | C37: Attribution rapide d'un événement extrême | D37: Immédiat | E37: 2 | F37: 3 | G37: 1 | H37: T36 | I37: mécanique centrale d'attribution. Sans elle, aucune catastrophe ne déplace de jauge
B38: A50 | C38: Révéler la majorité silencieuse | D38: Immédiat | E38: 3 | F38: 4 | G38: 1 | H38: T36 | I38: mécanique signature du jeu (écart 69 % réel / 43 % perçu). Usage limité par partie
B39: A51 | C39: Mobilisation de masse | D39: Court (1-2 tours) | E39: 3 | F39: 3 | G39: 1 | H39: T36 | I39: effet fort et rapidement amorti : bonne courbe de décision
B40: A53 | C40: Éducation et formation de masse | D40: Long (>5 tours) | E40: 2 | F40: 3 | G40: 1 | H40: — | I40: le seul levier lent et sûr : déplace le réel, incontrable
B41: A54 | C41: Journalisme d'investigation | D41: Court (1-2 tours) | E41: 3 | F41: 3 | G41: 2 | H41: T26 | I41: irréversible, détruit la crédibilité adverse. Un coup par cible
B42: A57 | C42: Récit de co-bénéfices | D42: Moyen (3-5 tours) | E42: 2 | F42: 4 | G42: 1 | H42: T38 | I42: santé, facture, air : plus efficace que le récit catastrophe
B44: Verrous — camp actif (7)
B45: Les irréversibles : c'est par là que le camp actif gagne
B46: ID | C46: Levier | D46: Latence | E46: Coût | F46: Puiss. | G46: Diff. | H46: Contre | I46: Rôle
...

Sheet Contrôles
B2: Contrôles de la sélection
B3: Toutes les valeurs sont calculées depuis l'onglet Catalogue.
B5: Répartition par verdict
B6: Verdict | C6: Nombre | D6: Puissance moy. | E6: Coût moy.
B7: Retenu | C7: =COUNTIF(Catalogue!$P$2:$P$135,$B7) -> 75 | D7: =IFERROR(AVERAGEIF(Catalogue!$P$2:$P$135,$B7,Catalogue!$J$2:$J$135),0) -> 3.8133333 | E7: =IFERROR(AVERAGEIF(Catalogue!$P$2:$P$135,$B7,Catalogue!$I$2:$I$135),0) -> 3.0533333
B8: À tester | C8: =COUNTIF(Catalogue!$P$2:$P$135,$B8) -> 43 | D8: =IFERROR(AVERAGEIF(Catalogue!$P$2:$P$135,$B8,Catalogue!$J$2:$J$135),0) -> 3.0232558 | E8: =IFERROR(AVERAGEIF(Catalogue!$P$2:$P$135,$B8,Catalogue!$I$2:$I$135),0) -> 2.8604651
B9: Écarté | C9: =COUNTIF(Catalogue!$P$2:$P$135,$B9) -> 16 | D9: =IFERROR(AVERAGEIF(Catalogue!$P$2:$P$135,$B9,Catalogue!$J$2:$J$135),0) -> 2.625 | E9: =IFERROR(AVERAGEIF(Catalogue!$P$2:$P$135,$B9,Catalogue!$I$2:$I$135),0) -> 2.5625
B11: Noyau par camp — l'asymétrie est-elle conservée ?
B12: Camp | C12: Retenus | D12: Puissance moy. | E12: Coût moy.
B13: Actif | C13: =COUNTIFS(Catalogue!$P$2:$P$135,"Retenu",Catalogue!$B$2:$B$135,$B13) -> 38 | D13: =IFERROR(AVERAGEIFS(Catalogue!$J$2:$J$135,Catalogue!$P$2:$P$135,"Retenu",Catalogue!$B$2:$B$135,$B13),0) -> 3.7894737 | E13: =IFERROR(AVERAGEIFS(Catalogue!$I$2:$I$135,Catalogue!$P$2:$P$135,"Retenu",Catalogue!$B$2:$B$135,$B13),0) -> 3.2894737
B14: Attentiste | C14: =COUNTIFS(Catalogue!$P$2:$P$135,"Retenu",Catalogue!$B$2:$B$135,$B14) -> 31 | D14: =IFERROR(AVERAGEIFS(Catalogue!$J$2:$J$135,Catalogue!$P$2:$P$135,"Retenu",Catalogue!$B$2:$B$135,$B14),0) -> 4.3870968 | E14: =IFERROR(AVERAGEIFS(Catalogue!$I$2:$I$135,Catalogue!$P$2:$P$135,"Retenu",Catalogue!$B$2:$B$135,$B14),0) -> 2.7096774
B15: Piège | C15: =COUNTIFS(Catalogue!$P$2:$P$135,"Retenu",Catalogue!$B$2:$B$135,$B15) -> 6 | D15: =IFERROR(AVERAGEIFS(Catalogue!$J$2:$J$135,Catalogue!$P$2:$P$135,"Retenu",Catalogue!$B$2:$B$135,$B15),0) -> 1 | E15: =IFERROR(AVERAGEIFS(Catalogue!$I$2:$I$135,Catalogue!$P$2:$P$135,"Retenu",Catalogue!$B$2:$B$135,$B15),0) -> 3.3333333
B17: Référence catalogue complet | C17: 134 | D17: Actif 3,4 / Attentiste 4,0 | E17: 3,2 / 2,6
B19: Déblocage par niveau de difficulté
B20: Niveau | C20: Nouvelles cartes | D20: Cumul jouable
B21: 1 — Découverte | C21: =COUNTIFS(Catalogue!$P$2:$P$135,"Retenu",Catalogue!$N$2:$N$135,1) -> 34 | D21: =COUNTIFS(Catalogue!$P$2:$P$135,"Retenu",Catalogue!$N$2:$N$135,"<="&1) -> 34
B22: 2 — Standard | C22: =COUNTIFS(Catalogue!$P$2:$P$135,"Retenu",Catalogue!$N$2:$N$135,2) -> 28 | D22: =COUNTIFS(Catalogue!$P$2:$P$135,"Retenu",Catalogue!$N$2:$N$135,"<="&2) -> 62
B23: 3 — Réaliste | C23: =COUNTIFS(Catalogue!$P$2:$P$135,"Retenu",Catalogue!$N$2:$N$135,3) -> 13 | D23: =COUNTIFS(Catalogue!$P$2:$P$135,"Retenu",Catalogue!$N$2:$N$135,"<="&3) -> 75
B24: 4 — Expert | C24: =COUNTIFS(Catalogue!$P$2:$P$135,"Retenu",Catalogue!$N$2:$N$135,4) -> 0 | D24: =COUNTIFS(Catalogue!$P$2:$P$135,"Retenu",Catalogue!$N$2:$N$135,"<="&4) -> 75
B26: Contrôle de cohérence des contre-leviers
B27: Règle : tout levier retenu doit avoir son contre-levier retenu, sinon il est imblocable ou sans cible.
B28: Levier retenu | C28: Contre-levier attendu | D28: Statut du contre | E28: Décision
B29: A27 — Retrait de l'assurance sur les projets fossiles | C29: T49 — Sortie d'une alliance climatique | D29: À tester | E29: Trou assumé — A27 reste contré indirectement par T43 (verrouillage) et T46 (cession d'actifs)
B30: T31 — Greenwashing publicitaire | C30: A37 — Contentieux publicité mensongère / climate-washing | D30: À tester | E30: Trou assumé — A17 (interdiction de la publicité fossile) le couvre partiellement
B32: Trous restants : 2 sur 75 leviers retenus
B35: Paires piège / levier légitime — à conserver ou à retirer ensemble
B36: Levier légitime | C36: Piège jumeau | D36: Ce que la paire enseigne
B37: A44 — CCS industriel | C37: P07 — CCS sur centrale | D37: Même technologie : un usage défendable, un usage de report
B38: A47 — Hydrogène industrie | C38: P04 — Hydrogène voiture | D38: Même vecteur : pertinent où l'électrification directe est impossible, absurde ailleurs
B39: A46 — Programme nucléaire | C39: P10 — Nucléaire pour 2030 | D39: Le levier est réel, c'est le CALENDRIER qui est le piège
B40: A02 — Marché de quotas | C40: P01 — Compensation volontaire | D40: Un plafond contraignant contre un crédit non additionnel
B42: Attention : A44 et A47 sont actuellement en « À tester » alors que leurs pièges jumeaux P07 et P04 sont retenus.
B43: Décision à prendre : remonter A44 et A47 dans le noyau, ou redescendre P07 et P04.
